Workbook

Sheet Read Me
B2: Transaction Experience — LBO returns models
B3: Built on the Leland LBO Modeling template (September 2026). The original template sheets are preserved unchanged at the end of the workbook.
B5: WHAT IS HERE
B6: Summary — one row per deal with entry structure, underwritten returns (template run on the entry facts) and actual returns where an exit is disclosed.
B7: P01–P11 — Paper LBO tabs, one per deal, in the template's own layout. Cells B2:J49 are the template; the INPUTS block at L4:P20 drives them and carries a source and a tag for every number. Rows 52–77 hold the actual outcome and notes.
B8: F01–F04 — Full LBO Model Solution tabs for the four deals with enough filed data: KKR/Varsity 2024, Bain/Varsity 2018, Cerberus/Chrysler 2007, Caterpillar/Bucyrus 2011.
B9: M01–M02 — Sunoco LP acquisition models (NuStar 2024, Parkland 2025): accretion/dilution to distributable cash flow per unit and pro forma net debt / EBITDA, year 1 to year 3. These are strategic MLP acquisitions, not LBOs, and are built as the acquirer's board would have looked at them. Inputs are tagged like the other tabs.
B10: HOW TO READ THE TAGS
B11: F = filed or rating-agency figure (SEC filing, court record, Moody's/S&P release, company release). P = press-reported (Reuters, LCD, Bloomberg, trade press). A = assumption, shown in blue on a yellow fill. Change any blue cell and the tab recalculates.
B13: TWO DEALS ARE NOT LBOs
B14: P07 Caterpillar/Bucyrus and P08 NRG/Direct Energy were strategic acquisitions financed with corporate notes. They are included, with a red banner, because the template mechanics still answer the question "what did the price require", and because both are among the best-documented transactions in the book. Their "equity" is the acquirer's cash, not sponsor equity, and there was no exit.
B16: ONE DEAL NEVER HAPPENED
... B26: Compiled 6 September 2026 from the sources listed on each tab. Not investment advice.

Sheet Summary
B2: Transaction Experience — LBO returns models
B3: Underwritten case = the template run on the entry structure and stated assumptions. Actual = the realised exit where one exists. All figures US$ millions. Blue cells on the deal tabs are assumptions.
B5: # | C5: Deal | D5: Classification | E5: Status | F5: Entry EV | G5: Entry EBITDA | H5: Entry x | I5: Debt | J5: Leverage x | K5: Equity | L5: Exit x | M5: MoM (uw) | N5: IRR (uw) | O5: MoM (actual) | P5: IRR (actual) | Q5: Full model tab
B6: 1 | C6: KKR / Varsity Brands (2024) | D6: Sponsor buyout | E6: Pending (hold) | F6: ='P01 KKR-Varsity 2024'!N5 | G6: ='P01 KKR-Varsity 2024'!N6 | H6: ='P01 KKR-Varsity 2024'!N7 | I6: ='P01 KKR-Varsity 2024'!N8 | J6: ='P01 KKR-Varsity 2024'!N9 | K6: ='P01 KKR-Varsity 2024'!E6 | L6: ='P01 KKR-Varsity 2024'!N18 | M6: ='P01 KKR-Varsity 2024'!E45 | N6: ='P01 KKR-Varsity 2024'!E46 | O6: n/a | P6: n/a | Q6: F01 KKR-Varsity 2024
B7: 2 | C7: Bain Capital / Varsity Brands (2018-24) | D7: Secondary buyout | E7: Realised Aug-2024 | F7: ='P02 Bain-Varsity 2018'!N5 | G7: ='P02 Bain-Varsity 2018'!N6 | H7: ='P02 Bain-Varsity 2018'!N7 | I7: ='P02 Bain-Varsity 2018'!N8 | J7: ='P02 Bain-Varsity 2018'!N9 | K7: ='P02 Bain-Varsity 2018'!E6 | L7: ='P02 Bain-Varsity 2018'!N18 | M7: ='P02 Bain-Varsity 2018'!E45 | N7: ='P02 Bain-Varsity 2018'!E46 | O7: ='P02 Bain-Varsity 2018'!E57 | P7: ='P02 Bain-Varsity 2018'!E58 | Q7: F02 Bain-Varsity 2018
B8: 3 | C8: Charlesbank + Partners Group / Varsity Brands (2014-18) | D8: ESOP buyout | E8: Realised Jul-2018 | F8: ='P03 Charlesbank-Varsity 2014'!N5 | G8: ='P03 Charlesbank-Varsity 2014'!N6 | H8: ='P03 Charlesbank-Varsity 2014'!N7 | I8: ='P03 Charlesbank-Varsity 2014'!N8 | J8: ='P03 Charlesbank-Varsity 2014'!N9 | K8: ='P03 Charlesbank-Varsity 2014'!E6 | L8: ='P03 Charlesbank-Varsity 2014'!N18 | M8: ='P03 Charlesbank-Varsity 2014'!E45 | N8: ='P03 Charlesbank-Varsity 2014'!E46 | O8: ='P03 Charlesbank-Varsity 2014'!E57 | P8: ='P03 Charlesbank-Varsity 2014'!E58
B9: 4 | C9: Leonard Green / Varsity Brands (2003-11) | D9: Take-private (13E-3) | E9: Realised Aug-2011 (price undisclosed) | F9: ='P04 LGP-Varsity 2003'!N5 | G9: ='P04 LGP-Varsity 2003'!N6 | H9: ='P04 LGP-Varsity 2003'!N7 | I9: ='P04 LGP-Varsity 2003'!N8 | J9: ='P04 LGP-Varsity 2003'!N9 | K9: ='P04 LGP-Varsity 2003'!E6 | L9: ='P04 LGP-Varsity 2003'!N18 | M9: ='P04 LGP-Varsity 2003'!E45 | N9: ='P04 LGP-Varsity 2003'!E46 | O9: n/a | P9: n/a
B10: 5 | C10: ONCAP / Sport Supply Group (2010-13) | D10: Take-private with rollover | E10: Realised Jun-2013 (price undisclosed) | F10: ='P05 ONCAP-SportSupply 2010'!N5 | G10: ='P05 ONCAP-SportSupply 2010'!N6 | H10: ='P05 ONCAP-SportSupply 2010'!N7 | I10: ='P05 ONCAP-SportSupply 2010'!N8 | J10: ='P05 ONCAP-SportSupply 2010'!N9 | K10: ='P05 ONCAP-SportSupply 2010'!E6 | L10: ='P05 ONCAP-SportSupply 2010'!N18 | M10: ='P05 ONCAP-SportSupply 2010'!E45 | N10: ='P05 ONCAP-SportSupply 2010'!E46 | O10: n/a | P10: n/a
B11: 6 | C11: Cerberus / Chrysler (2007-09) | D11: Private equity carve-out | E11: Realised 2009: equity written to zero | F11: ='P06 Cerberus-Chrysler 2007'!N5 | G11: ='P06 Cerberus-Chrysler 2007'!N6 | H11: ='P06 Cerberus-Chrysler 2007'!N7 | I11: ='P06 Cerberus-Chrysler 2007'!N8 | J11: ='P06 Cerberus-Chrysler 2007'!N9 | K11: ='P06 Cerberus-Chrysler 2007'!E6 | L11: ='P06 Cerberus-Chrysler 2007'!N18 | M11: ='P06 Cerberus-Chrysler 2007'!E45 | N11: ='P06 Cerberus-Chrysler 2007'!E46 | O11: ='P06 Cerberus-Chrysler 2007'!E57 | P11: ='P06 Cerberus-Chrysler 2007'!E58 | Q11: F03 Cerberus-Chrysler 2007
B12: 7 | C12: Caterpillar / Bucyrus (2011) [STRATEGIC] | D12: STRATEGIC public M&A, debt-financed (not an LBO) | E12: Held; $595m goodwill impairment Q4-2016 | F12: ='P07 Caterpillar-Bucyrus 2011'!N5 | G12: ='P07 Caterpillar-Bucyrus 2011'!N6 | H12: ='P07 Caterpillar-Bucyrus 2011'!N7 | I12: ='P07 Caterpillar-Bucyrus 2011'!N8 | J12: ='P07 Caterpillar-Bucyrus 2011'!N9 | K12: ='P07 Caterpillar-Bucyrus 2011'!E6 | L12: ='P07 Caterpillar-Bucyrus 2011'!N18 | M12: ='P07 Caterpillar-Bucyrus 2011'!E45 | N12: ='P07 Caterpillar-Bucyrus 2011'!E46 | O12: n/a | P12: n/a | Q12: F04 CAT-Bucyrus 2011 STRAT
B13: 8 | C13: NRG / Direct Energy (2021) [STRATEGIC] | D13: STRATEGIC corporate carve-out, note-financed (not an LBO) | E13: Held; $300m synergy programme completed 2023 | F13: ='P08 NRG-DirectEnergy 2021'!N5 | G13: ='P08 NRG-DirectEnergy 2021'!N6 | H13: ='P08 NRG-DirectEnergy 2021'!N7 | I13: ='P08 NRG-DirectEnergy 2021'!N8 | J13: ='P08 NRG-DirectEnergy 2021'!N9 | K13: ='P08 NRG-DirectEnergy 2021'!E6 | L13: ='P08 NRG-DirectEnergy 2021'!N18 | M13: ='P08 NRG-DirectEnergy 2021'!E45 | N13: ='P08 NRG-DirectEnergy 2021'!E46 | O13: n/a | P13: n/a
B14: 9 | C14: Wind Point / Pacific Cycle (2000-04) | D14: Sponsor platform build and exit | E14: Realised Feb-2004 | F14: ='P09 WindPoint-Pacific 2001'!N5 | G14: ='P09 WindPoint-Pacific 2001'!N6 | H14: ='P09 WindPoint-Pacific 2001'!N7 | I14: ='P09 WindPoint-Pacific 2001'!N8 | J14: ='P09 WindPoint-Pacific 2001'!N9 | K14: ='P09 WindPoint-Pacific 2001'!E6 | L14: ='P09 WindPoint-Pacific 2001'!N18 | M14: ='P09 WindPoint-Pacific 2001'!E45 | N14: ='P09 WindPoint-Pacific 2001'!E46 | O14: ='P09 WindPoint-Pacific 2001'!E57 | P14: ='P09 WindPoint-Pacific 2001'!E58
B15: 10 | C15: Pegasus Capital / Cannondale (2003-08) | D15: Distressed 363 purchase and exit | E15: Realised Q1-2008 | F15: ='P10 Pegasus-Cannondale 2003'!N5 | G15: ='P10 Pegasus-Cannondale 2003'!N6 | H15: ='P10 Pegasus-Cannondale 2003'!N7 | I15: ='P10 Pegasus-Cannondale 2003'!N8 | J15: ='P10 Pegasus-Cannondale 2003'!N9 | K15: ='P10 Pegasus-Cannondale 2003'!E6 | L15: ='P10 Pegasus-Cannondale 2003'!N18 | M15: ='P10 Pegasus-Cannondale 2003'!E45 | N15: ='P10 Pegasus-Cannondale 2003'!E46 | O15: ='P10 Pegasus-Cannondale 2003'!E57 | P15: ='P10 Pegasus-Cannondale 2003'!E58
B16: 11 | C16: Cerberus + Koch / Dorel (2021) [TERMINATED] | D16: Take-private with family rollover (terminated 15 Feb 2021) | E16: Terminated; counterfactual shown | F16: ='P11 Cerberus-Dorel 2021 TERM'!N5 | G16: ='P11 Cerberus-Dorel 2021 TERM'!N6 | H16: ='P11 Cerberus-Dorel 2021 TERM'!N7 | I16: ='P11 Cerberus-Dorel 2021 TERM'!N8 | J16: ='P11 Cerberus-Dorel 2021 TERM'!N9 | K16: ='P11 Cerberus-Dorel 2021 TERM'!E6 | L16: ='P11 Cerberus-Dorel 2021 TERM'!N18 | M16: ='P11 Cerberus-Dorel 2021 TERM'!E45 | N16: ='P11 Cerberus-Dorel 2021 TERM'!E46 | O16: ='P11 Cerberus-Dorel 2021 TERM'!E57 | P16: ='P11 Cerberus-Dorel 2021 TERM'!E58
B18: Portfolio arithmetic (sponsor deals only, excluding the two strategic rows and the terminated deal)
B19: Deals with a realised, disclosed exit | F19: =COUNTIF(O6:O16,">0")
B20: Median MoM, underwritten (all rows) | F20: =MEDIAN(M6:M16)
B21: Median MoM, actual (where disclosed) | F21: =IFERROR(MEDIAN(O6:O16),"n/a")
B22: Aggregate entry EV, all rows | F22: =SUM(F6:F16)
B25: Acquisition models (Sunoco LP; strategic, not LBOs)
B26: # | C26: Deal | D26: Classification | E26: Status | F26: Target EV | G26: Target EBITDA | H26: EV / EBITDA | I26: Units issued (m) | J26: Accretion Y1 | K26: Accretion Y3 | L26: Leverage at close | M26: Leverage Y3 | N26: Mgmt accretion target
B27: M1 | C27: Sunoco LP / NuStar Energy L.P. (2024) | D27: All-equity MLP merger | E27: Closed 3 May 2024 | F27: ='M01 SUN-NuStar 2024'!C48 | G27: ='M01 SUN-NuStar 2024'!E20 | H27: ='M01 SUN-NuStar 2024'!C49 | I27: ='M01 SUN-NuStar 2024'!E30 | J27: ='M01 SUN-NuStar 2024'!C62 | K27: ='M01 SUN-NuStar 2024'!E62 | L27: ='M01 SUN-NuStar 2024'!C70 | M27: ='M01 SUN-NuStar 2024'!E75 | N27: 10%+ by year 3
B28: M2 | C28: Sunoco LP / Parkland Corporation (2025) | D28: Cash-and-units plan of arrangement | E28: Closed 31 Oct 2025 | F28: ='M02 SUN-Parkland 2025'!C48 | G28: ='M02 SUN-Parkland 2025'!E20 | H28: ='M02 SUN-Parkland 2025'!C49 | I28: ='M02 SUN-Parkland 2025'!E30 | J28: ='M02 SUN-Parkland 2025'!C62 | K28: ='M02 SUN-Parkland 2025'!E62 | L28: ='M02 SUN-Parkland 2025'!C70 | M28: ='M02 SUN-Parkland 2025'!E75 | N28: 10%+ by year 3

Sheet P01 KKR-Varsity 2024
B2: KKR / Varsity Brands (2024) — Paper LBO
B4: Sources | G4: Uses | L4: INPUTS | N4: Value | O4: Tag | P4: Source (F = filed / rating agency, P = press, A = assumption; blue = assumption)
B5: Debt | E5: =E12 | G5: Purchase Price | J5: =J12 | L5: Entry enterprise value ($m) | N5: 4750 | O5: P | P5: PitchBook LCD / Sportico
B6: Equity (plug) | E6: =E7-E5 | L6: Entry EBITDA, LTM ($m) | N6: 400 | O6: P | P6: Trade press '>$400m'; Moody's 6.2x on ~$2.48bn debt implies ~$400m
B7: Total Sources | E7: =J7 | G7: Total Uses | J7: =J5 | L7: Entry multiple (x) | N7: =N5/N6 | O7: calc | P7: Derived
L8: Debt raised ($m) | N8: 2475 | O8: F | P8: $2,375m TLB + $100m ABL drawn at close (LCD, Sportico)
B9: Build to Debt | G9: Build to Purchase Price | L9: Leverage (x EBITDA) | N9: =N8/N6 | O9: calc | P9: Derived
B10: 2024 EBITDA (LTM) | E10: =E18 | G10: 2024 EBITDA (LTM) | J10: =E18 | L10: Blended cash interest rate | N10: 0.0905 | O10: F | P10: TLB S+375 (fund holdings show TSFR3M+3.75%); 3M SOFR ~5.30% Aug-2024
B11: (x) Leverage | E11: =N9 | G11: (x) Multiple of 2023 EBITDA | J11: =N7 | L11: Tax rate | N11: 0.25 | O11: A | P11: Blended US federal+state assumption
B12: Debt | E12: =E10*E11 | G12: Purchase Price | J12: =J10*J11 | L12: Base-year revenue ($m) | N12: 2600 | O12: F | P12: Moody's: ~$2.6bn LTM Mar-2025 (SGB Media, Jul 2025)
L13: Incremental revenue p.a. ($m) | N13: 130 | O13: A | P13: 5% p.a.; Moody's projected mid-single-digit growth
B14: Simple P&L | E14: 2024 | F14: =E14+1 | G14: =F14+1 | H14: =G14+1 | I14: =H14+1 | J14: =I14+1 | L14: EBITDA margin, base year | N14: =N6/N12 | O14: calc | P14: Derived
B15: Revenue | E15: =N12 | F15: =E15+F16 | G15: =F15+G16 | H15: =G15+H16 | I15: =H15+I16 | J15: =I15+J16 | L15: D&A p.a. ($m) | N15: 78 | O15: A | P15: 3.0% of revenue, assumption
B16: $ Incremental Revenue | F16: =N13 | G16: =F16 | H16: =G16 | I16: =H16 | J16: =I16 | L16: Capex p.a. ($m) | N16: 62 | O16: A | P16: 80% of D&A, assumption
L17: Change in NWC p.a. ($m, negative = investment) | N17: 0 | O17: A | P17: Assumed flat
B18: EBITDA | E18: =E19*E15 | F18: =F19*F15 | G18: =G19*G15 | H18: =H19*H15 | I18: =I19*I15 | J18: =J19*J15 | L18: Exit multiple (x) | N18: 11 | O18: A | P18: Entry 11.9x; modest compression assumed
B19: % margin | E19: =N14 | F19: =E19 | G19: =F19 | H19: =G19 | I19: =H19 | J19: =I19 | L19: Entry date | N19: 45530 | O19: F | P19: Closing date per filings
L20: Underwritten exit date (5-year hold) | N20: 47356 | O20: A | P20: Template convention: five projection years
B21: LFCF Build | L21: Actual exit / valuation date | N21: n/a | O21: F | P21: No realised exit
B22: EBITDA | F22: =F18 | G22: =G18 | H22: =H18 | I22: =I18 | J22: =J18
B23: (-) D&A | F23: =-$N$15 | G23: =-$N$15 | H23: =-$N$15 | I23: =-$N$15 | J23: =-$N$15
B24: EBIT | F24: =F22+F23 | G24: =G22+G23 | H24: =H22+H23 | I24: =I22+I23 | J24: =J22+J23
B25: (-) Cash Interest | D25: =N10 | F25: =$E$12*-$D$25 | G25: =$E$12*-$D$25 | H25: =$E$12*-$D$25 | I25: =$E$12*-$D$25 | J25: =$E$12*-$D$25
B26: EBT | F26: =F24+F25 | G26: =G24+G25 | H26: =H24+H25 | I26: =I24+I25 | J26: =J24+J25
B27: (-) Taxes | D27: =N11 | F27: =F26*-$D27 | G27: =G26*-$D27 | H27: =H26*-$D27 | I27: =I26*-$D27 | J27: =J26*-$D27
B28: Net Income | F28: =F26+F27 | G28: =G26+G27 | H28: =H26+H27 | I28: =I26+I27 | J28: =J26+J27
B29: (+) D&A | F29: =-F23 | G29: =-G23 | H29: =-H23 | I29: =-I23 | J29: =-J23
B30: (-) Capex | F30: =-$N$16 | G30: =-$N$16 | H30: =-$N$16 | I30: =-$N$16 | J30: =-$N$16
B31: (-) Change in NWC | F31: =$N$17 | G31: =$N$17 | H31: =$N$17 | I31: =$N$17 | J31: =$N$17
B32: Levered FCF | F32: =SUM(F28:F31) | G32: =SUM(G28:G31) | H32: =SUM(H28:H31) | I32: =SUM(I28:I31) | J32: =SUM(J28:J31)
B33: Cumulative LFCF | F33: =SUM($E32:F32) | G33: =SUM($E32:G32) | H33: =SUM($E32:H32) | I33: =SUM($E32:I32) | J33: =SUM($E32:J32)
B35: Returns — UNDERWRITTEN CASE (template mechanics: interest on opening debt, all LFCF accumulates as cash)
B37: Exit EBITDA (2029) | E37: =J18
B38: (x) Exit Multiple | E38: =N18
B39: Enterprise Value | E39: =E37*E38
B40: (-) Debt | E40: =-E12
B41: (+) Cash | E41: =J33
B42: Equity Value at Exit | E42: =SUM(E39:E41)
B43: Initial Equity Investment | E43: =E6
B45: MoM | E45: =E42/E43
...

Sheet P02 Bain-Varsity 2018
B2: Bain Capital / Varsity Brands (2018-24) — Paper LBO
B4: Sources | G4: Uses | L4: INPUTS | N4: Value | O4: Tag | P4: Source (F = filed / rating agency, P = press, A = assumption; blue = assumption)
B5: Debt | E5: =E12 | G5: Purchase Price | J5: =J12 | L5: Entry enterprise value ($m) | N5: 2900 | O5: F | P5: Moody's: 'total implied enterprise value of approximately $2.9 billion' (press said ~$2.5bn)
B6: Equity (plug) | E6: =E7-E5 | L6: Entry EBITDA, LTM ($m) | N6: 290 | O6: A | P6: Assumption: $2.9bn EV at 10.0x; Moody's showed 7.7x on ~$2.0bn debt at Dec-2019 (~$260m)
B7: Total Sources | E7: =J7 | G7: Total Uses | J7: =J5 | L7: Entry multiple (x) | N7: =N5/N6 | O7: calc | P7: Derived
L8: Debt raised ($m) | N8: 1990 | O8: F | P8: $1,370m 1L TL + $620m 2L TL (Moody's); $180m revolver undrawn
B9: Build to Debt | G9: Build to Purchase Price | L9: Leverage (x EBITDA) | N9: =N8/N6 | O9: calc | P9: Derived
B10: 2018 EBITDA (LTM) | E10: =E18 | G10: 2018 EBITDA (LTM) | J10: =E18 | L10: Blended cash interest rate | N10: 0.0715 | O10: A | P10: 1L L+350 (~5.75%) and 2L assumed L+800 (~10.25%), blended
B11: (x) Leverage | E11: =N9 | G11: (x) Multiple of 2023 EBITDA | J11: =N7 | L11: Tax rate | N11: 0.25 | O11: A | P11: Assumption
B12: Debt | E12: =E10*E11 | G12: Purchase Price | J12: =J10*J11 | L12: Base-year revenue ($m) | N12: 2000 | O12: F | P12: Moody's: ~$2.0bn LTM Dec-2019
L13: Incremental revenue p.a. ($m) | N13: 120 | O13: A | P13: Path to ~$400m EBITDA by 2023 at constant margin (6% p.a.)
B14: Simple P&L | E14: 2018 | F14: =E14+1 | G14: =F14+1 | H14: =G14+1 | I14: =H14+1 | J14: =I14+1 | L14: EBITDA margin, base year | N14: =N6/N12 | O14: calc | P14: Derived
B15: Revenue | E15: =N12 | F15: =E15+F16 | G15: =F15+G16 | H15: =G15+H16 | I15: =H15+I16 | J15: =I15+J16 | L15: D&A p.a. ($m) | N15: 60 | O15: A | P15: 3.0% of revenue, assumption
B16: $ Incremental Revenue | F16: =N13 | G16: =F16 | H16: =G16 | I16: =H16 | J16: =I16 | L16: Capex p.a. ($m) | N16: 50 | O16: A | P16: Assumption
L17: Change in NWC p.a. ($m, negative = investment) | N17: 0 | O17: A | P17: Assumed flat
B18: EBITDA | E18: =E19*E15 | F18: =F19*F15 | G18: =G19*G15 | H18: =H19*H15 | I18: =I19*I15 | J18: =J19*J15 | L18: Exit multiple (x) | N18: 11.875 | O18: P | P18: $4,750m KKR price on ~$400m EBITDA
B19: % margin | E19: =N14 | F19: =E19 | G19: =F19 | H19: =G19 | I19: =H19 | J19: =I19 | L19: Entry date | N19: 43312 | O19: F | P19: Closing date per filings
L20: Underwritten exit date (5-year hold) | N20: 45135 | O20: A | P20: Template convention: five projection years
B21: LFCF Build | L21: Actual exit / valuation date | N21: 45530 | O21: F | P21: Realised exit date per filings
B22: EBITDA | F22: =F18 | G22: =G18 | H22: =H18 | I22: =I18 | J22: =J18
B23: (-) D&A | F23: =-$N$15 | G23: =-$N$15 | H23: =-$N$15 | I23: =-$N$15 | J23: =-$N$15
B24: EBIT | F24: =F22+F23 | G24: =G22+G23 | H24: =H22+H23 | I24: =I22+I23 | J24: =J22+J23
B25: (-) Cash Interest | D25: =N10 | F25: =$E$12*-$D$25 | G25: =$E$12*-$D$25 | H25: =$E$12*-$D$25 | I25: =$E$12*-$D$25 | J25: =$E$12*-$D$25
B26: EBT | F26: =F24+F25 | G26: =G24+G25 | H26: =H24+H25 | I26: =I24+I25 | J26: =J24+J25
B27: (-) Taxes | D27: =N11 | F27: =F26*-$D27 | G27: =G26*-$D27 | H27: =H26*-$D27 | I27: =I26*-$D27 | J27: =J26*-$D27
B28: Net Income | F28: =F26+F27 | G28: =G26+G27 | H28: =H26+H27 | I28: =I26+I27 | J28: =J26+J27
B29: (+) D&A | F29: =-F23 | G29: =-G23 | H29: =-H23 | I29: =-I23 | J29: =-J23
B30: (-) Capex | F30: =-$N$16 | G30: =-$N$16 | H30: =-$N$16 | I30: =-$N$16 | J30: =-$N$16
B31: (-) Change in NWC | F31: =$N$17 | G31: =$N$17 | H31: =$N$17 | I31: =$N$17 | J31: =$N$17
B32: Levered FCF | F32: =SUM(F28:F31) | G32: =SUM(G28:G31) | H32: =SUM(H28:H31) | I32: =SUM(I28:I31) | J32: =SUM(J28:J31)
B33: Cumulative LFCF | F33: =SUM($E32:F32) | G33: =SUM($E32:G32) | H33: =SUM($E32:H32) | I33: =SUM($E32:I32) | J33: =SUM($E32:J32)
B35: Returns — UNDERWRITTEN CASE (template mechanics: interest on opening debt, all LFCF accumulates as cash)
B37: Exit EBITDA (2023) | E37: =J18
B38: (x) Exit Multiple | E38: =N18
B39: Enterprise Value | E39: =E37*E38
B40: (-) Debt | E40: =-E12
B41: (+) Cash | E41: =J33
B42: Equity Value at Exit | E42: =SUM(E39:E41)
B43: Initial Equity Investment | E43: =E6
B45: MoM | E45: =E42/E43
...

Sheet P03 Charlesbank-Varsity 2014
B2: Charlesbank + Partners Group / Varsity Brands (2014-18) — Paper LBO
B4: Sources | G4: Uses | L4: INPUTS | N4: Value | O4: Tag | P4: Source (F = filed / rating agency, P = press, A = assumption; blue = assumption)
B5: Debt | E5: =E12 | G5: Purchase Price | J5: =J12 | L5: Entry enterprise value ($m) | N5: 1500 | O5: P | P5: Charlesbank site / CNBC '~$1.5bn'
B6: Equity (plug) | E6: =E7-E5 | L6: Entry EBITDA, LTM ($m) | N6: 155 | O6: A | P6: Assumption: ~9.7x entry on $1.5bn; B2 CFR at 6.5x leverage
B7: Total Sources | E7: =J7 | G7: Total Uses | J7: =J5 | L7: Entry multiple (x) | N7: =N5/N6 | O7: calc | P7: Derived
L8: Debt raised ($m) | N8: 1000 | O8: A | P8: Assumption: 1L (L+500, 1% floor) ~$700m + 2L (L+875) ~$300m; Ares held $175m of 2L par
B9: Build to Debt | G9: Build to Purchase Price | L9: Leverage (x EBITDA) | N9: =N8/N6 | O9: calc | P9: Derived
B10: 2014 EBITDA (LTM) | E10: =E18 | G10: 2014 EBITDA (LTM) | J10: =E18 | L10: Blended cash interest rate | N10: 0.0713 | O10: F | P10: 1L 6.00% and 2L 9.75% (BDC filings), blended 70/30
B11: (x) Leverage | E11: =N9 | G11: (x) Multiple of 2023 EBITDA | J11: =N7 | L11: Tax rate | N11: 0.3 | O11: A | P11: Assumption
B12: Debt | E12: =E10*E11 | G12: Purchase Price | J12: =J10*J11 | L12: Base-year revenue ($m) | N12: 1200 | O12: F | P12: Company release: 'combined sales in excess of $1.2 billion'
L13: Incremental revenue p.a. ($m) | N13: 80 | O13: A | P13: ~6.5% p.a., assumption
B14: Simple P&L | E14: 2014 | F14: =E14+1 | G14: =F14+1 | H14: =G14+1 | I14: =H14+1 | J14: =I14+1 | L14: EBITDA margin, base year | N14: =N6/N12 | O14: calc | P14: Derived
B15: Revenue | E15: =N12 | F15: =E15+F16 | G15: =F15+G16 | H15: =G15+H16 | I15: =H15+I16 | J15: =I15+J16 | L15: D&A p.a. ($m) | N15: 36 | O15: A | P15: 3.0% of revenue, assumption
B16: $ Incremental Revenue | F16: =N13 | G16: =F16 | H16: =G16 | I16: =H16 | J16: =I16 | L16: Capex p.a. ($m) | N16: 30 | O16: A | P16: Assumption
L17: Change in NWC p.a. ($m, negative = investment) | N17: 0 | O17: A | P17: Assumed flat
B18: EBITDA | E18: =E19*E15 | F18: =F19*F15 | G18: =G19*G15 | H18: =H19*H15 | I18: =I19*I15 | J18: =J19*J15 | L18: Exit multiple (x) | N18: 10 | O18: A | P18: $2.9bn Bain EV on ~$290m EBITDA (assumption)
B19: % margin | E19: =N14 | F19: =E19 | G19: =F19 | H19: =G19 | I19: =H19 | J19: =I19 | L19: Entry date | N19: 41988 | O19: F | P19: Closing date per filings
L20: Underwritten exit date (5-year hold) | N20: 43814 | O20: A | P20: Template convention: five projection years
B21: LFCF Build | L21: Actual exit / valuation date | N21: 43312 | O21: F | P21: Realised exit date per filings
B22: EBITDA | F22: =F18 | G22: =G18 | H22: =H18 | I22: =I18 | J22: =J18
B23: (-) D&A | F23: =-$N$15 | G23: =-$N$15 | H23: =-$N$15 | I23: =-$N$15 | J23: =-$N$15
B24: EBIT | F24: =F22+F23 | G24: =G22+G23 | H24: =H22+H23 | I24: =I22+I23 | J24: =J22+J23
B25: (-) Cash Interest | D25: =N10 | F25: =$E$12*-$D$25 | G25: =$E$12*-$D$25 | H25: =$E$12*-$D$25 | I25: =$E$12*-$D$25 | J25: =$E$12*-$D$25
B26: EBT | F26: =F24+F25 | G26: =G24+G25 | H26: =H24+H25 | I26: =I24+I25 | J26: =J24+J25
B27: (-) Taxes | D27: =N11 | F27: =F26*-$D27 | G27: =G26*-$D27 | H27: =H26*-$D27 | I27: =I26*-$D27 | J27: =J26*-$D27
B28: Net Income | F28: =F26+F27 | G28: =G26+G27 | H28: =H26+H27 | I28: =I26+I27 | J28: =J26+J27
B29: (+) D&A | F29: =-F23 | G29: =-G23 | H29: =-H23 | I29: =-I23 | J29: =-J23
B30: (-) Capex | F30: =-$N$16 | G30: =-$N$16 | H30: =-$N$16 | I30: =-$N$16 | J30: =-$N$16
B31: (-) Change in NWC | F31: =$N$17 | G31: =$N$17 | H31: =$N$17 | I31: =$N$17 | J31: =$N$17
B32: Levered FCF | F32: =SUM(F28:F31) | G32: =SUM(G28:G31) | H32: =SUM(H28:H31) | I32: =SUM(I28:I31) | J32: =SUM(J28:J31)
B33: Cumulative LFCF | F33: =SUM($E32:F32) | G33: =SUM($E32:G32) | H33: =SUM($E32:H32) | I33: =SUM($E32:I32) | J33: =SUM($E32:J32)
B35: Returns — UNDERWRITTEN CASE (template mechanics: interest on opening debt, all LFCF accumulates as cash)
B37: Exit EBITDA (2019) | E37: =J18
B38: (x) Exit Multiple | E38: =N18
B39: Enterprise Value | E39: =E37*E38
B40: (-) Debt | E40: =-E12
B41: (+) Cash | E41: =J33
B42: Equity Value at Exit | E42: =SUM(E39:E41)
B43: Initial Equity Investment | E43: =E6
B45: MoM | E45: =E42/E43
...

Sheet P04 LGP-Varsity 2003
B2: Leonard Green / Varsity Brands (2003-11) — Paper LBO
B4: Sources | G4: Uses | L4: INPUTS | N4: Value | O4: Tag | P4: Source (F = filed / rating agency, P = press, A = assumption; blue = assumption)
B5: Debt | E5: =E12 | G5: Purchase Price | J5: =J12 | L5: Entry enterprise value ($m) | N5: 144.6 | O5: F | P5: Rothschild adjusted EV incl. $10.4m deal costs; $164.2m 'aggregate transaction value' incl. fees
B6: Equity (plug) | E6: =E7-E5 | L6: Entry EBITDA, LTM ($m) | N6: 20.7 | O6: F | P6: 2002A adjusted EBITDA $19.0m + $1.7m add-backs (SC 13E-3 Ex-99(c)(3))
B7: Total Sources | E7: =J7 | G7: Total Uses | J7: =J5 | L7: Entry multiple (x) | N7: =N5/N6 | O7: calc | P7: Derived
L8: Debt raised ($m) | N8: 85 | O8: A | P8: Assumption: Wells Fargo/Merrill senior ~$55m + NML/BancAmerica sub-debt ~$30m (sizes not in the DEFM14A extract)
B9: Build to Debt | G9: Build to Purchase Price | L9: Leverage (x EBITDA) | N9: =N8/N6 | O9: calc | P9: Derived
B10: 2002 EBITDA (LTM) | E10: =E18 | G10: 2002 EBITDA (LTM) | J10: =E18 | L10: Blended cash interest rate | N10: 0.081 | O10: A | P10: Senior ~6% / sub-debt ~12%, blended
B11: (x) Leverage | E11: =N9 | G11: (x) Multiple of 2023 EBITDA | J11: =N7 | L11: Tax rate | N11: 0.38 | O11: A | P11: Assumption
B12: Debt | E12: =E10*E11 | G12: Purchase Price | J12: =J10*J11 | L12: Base-year revenue ($m) | N12: 156.4 | O12: F | P12: Rothschild fairness materials: 2002A revenue (SC 13E-3 Ex-99(c)(2))
L13: Incremental revenue p.a. ($m) | N13: 14 | O13: F | P13: 2003E revenue $170.5m per Rothschild; ~9% p.a.
B14: Simple P&L | E14: 2002 | F14: =E14+1 | G14: =F14+1 | H14: =G14+1 | I14: =H14+1 | J14: =I14+1 | L14: EBITDA margin, base year | N14: =N6/N12 | O14: calc | P14: Derived
B15: Revenue | E15: =N12 | F15: =E15+F16 | G15: =F15+G16 | H15: =G15+H16 | I15: =H15+I16 | J15: =I15+J16 | L15: D&A p.a. ($m) | N15: 4.5 | O15: A | P15: Assumption ~2.9% of revenue
B16: $ Incremental Revenue | F16: =N13 | G16: =F16 | H16: =G16 | I16: =H16 | J16: =I16 | L16: Capex p.a. ($m) | N16: 4 | O16: A | P16: Assumption
L17: Change in NWC p.a. ($m, negative = investment) | N17: -1 | O17: A | P17: Growth working capital, assumption
B18: EBITDA | E18: =E19*E15 | F18: =F19*F15 | G18: =G19*G15 | H18: =H19*H15 | I18: =I19*I15 | J18: =J19*J15 | L18: Exit multiple (x) | N18: 7 | O18: A | P18: Assumed equal to entry (exit price to Herff Jones undisclosed)
B19: % margin | E19: =N14 | F19: =E19 | G19: =F19 | H19: =G19 | I19: =H19 | J19: =I19 | L19: Entry date | N19: 37888 | O19: F | P19: Closing date per filings
L20: Underwritten exit date (5-year hold) | N20: 39715 | O20: A | P20: Template convention: five projection years
B21: LFCF Build | L21: Actual exit / valuation date | N21: n/a | O21: F | P21: No realised exit
B22: EBITDA | F22: =F18 | G22: =G18 | H22: =H18 | I22: =I18 | J22: =J18
B23: (-) D&A | F23: =-$N$15 | G23: =-$N$15 | H23: =-$N$15 | I23: =-$N$15 | J23: =-$N$15
B24: EBIT | F24: =F22+F23 | G24: =G22+G23 | H24: =H22+H23 | I24: =I22+I23 | J24: =J22+J23
B25: (-) Cash Interest | D25: =N10 | F25: =$E$12*-$D$25 | G25: =$E$12*-$D$25 | H25: =$E$12*-$D$25 | I25: =$E$12*-$D$25 | J25: =$E$12*-$D$25
B26: EBT | F26: =F24+F25 | G26: =G24+G25 | H26: =H24+H25 | I26: =I24+I25 | J26: =J24+J25
B27: (-) Taxes | D27: =N11 | F27: =F26*-$D27 | G27: =G26*-$D27 | H27: =H26*-$D27 | I27: =I26*-$D27 | J27: =J26*-$D27
B28: Net Income | F28: =F26+F27 | G28: =G26+G27 | H28: =H26+H27 | I28: =I26+I27 | J28: =J26+J27
B29: (+) D&A | F29: =-F23 | G29: =-G23 | H29: =-H23 | I29: =-I23 | J29: =-J23
B30: (-) Capex | F30: =-$N$16 | G30: =-$N$16 | H30: =-$N$16 | I30: =-$N$16 | J30: =-$N$16
B31: (-) Change in NWC | F31: =$N$17 | G31: =$N$17 | H31: =$N$17 | I31: =$N$17 | J31: =$N$17
B32: Levered FCF | F32: =SUM(F28:F31) | G32: =SUM(G28:G31) | H32: =SUM(H28:H31) | I32: =SUM(I28:I31) | J32: =SUM(J28:J31)
B33: Cumulative LFCF | F33: =SUM($E32:F32) | G33: =SUM($E32:G32) | H33: =SUM($E32:H32) | I33: =SUM($E32:I32) | J33: =SUM($E32:J32)
B35: Returns — UNDERWRITTEN CASE (template mechanics: interest on opening debt, all LFCF accumulates as cash)
B37: Exit EBITDA (2007) | E37: =J18
B38: (x) Exit Multiple | E38: =N18
B39: Enterprise Value | E39: =E37*E38
B40: (-) Debt | E40: =-E12
B41: (+) Cash | E41: =J33
B42: Equity Value at Exit | E42: =SUM(E39:E41)
B43: Initial Equity Investment | E43: =E6
B45: MoM | E45: =E42/E43
...

Sheet P05 ONCAP-SportSupply 2010
B2: ONCAP / Sport Supply Group (2010-13) — Paper LBO
B4: Sources | G4: Uses | L4: INPUTS | N4: Value | O4: Tag | P4: Source (F = filed / rating agency, P = press, A = assumption; blue = assumption)
B5: Debt | E5: =E12 | G5: Purchase Price | J5: =J12 | L5: Entry enterprise value ($m) | N5: 180.2 | O5: F | P5: $179.4m equity consideration (SC 13E-3) + $0.8m net debt
B6: Equity (plug) | E6: =E7-E5 | L6: Entry EBITDA, LTM ($m) | N6: 25.8 | O6: F | P6: LTM adjusted EBITDA to 31 Mar 2010 (8-K Ex-99.1)
B7: Total Sources | E7: =J7 | G7: Total Uses | J7: =J5 | L7: Entry multiple (x) | N7: =N5/N6 | O7: calc | P7: Derived
L8: Debt raised ($m) | N8: 101.1 | O8: F | P8: DEFM14A: term loan $74.6m + Manulife mezz $26.5m; $25m revolver undrawn
B9: Build to Debt | G9: Build to Purchase Price | L9: Leverage (x EBITDA) | N9: =N8/N6 | O9: calc | P9: Derived
B10: 2010 EBITDA (LTM) | E10: =E18 | G10: 2010 EBITDA (LTM) | J10: =E18 | L10: Blended cash interest rate | N10: 0.076 | O10: A | P10: Term loan ~6% / mezz ~12%, blended (rates not disclosed)
B11: (x) Leverage | E11: =N9 | G11: (x) Multiple of 2023 EBITDA | J11: =N7 | L11: Tax rate | N11: 0.38 | O11: A | P11: Assumption
B12: Debt | E12: =E10*E11 | G12: Purchase Price | J12: =J10*J11 | L12: Base-year revenue ($m) | N12: 262 | O12: F | P12: LTM to Mar-2010: FY09 $250.2m, 9-mo FY10 $198.5m (8-K Ex-99.1)
L13: Incremental revenue p.a. ($m) | N13: 15 | O13: A | P13: ~6% p.a. plus nine bolt-ons under ONCAP, assumption
B14: Simple P&L | E14: 2010 | F14: =E14+1 | G14: =F14+1 | H14: =G14+1 | I14: =H14+1 | J14: =I14+1 | L14: EBITDA margin, base year | N14: =N6/N12 | O14: calc | P14: Derived
B15: Revenue | E15: =N12 | F15: =E15+F16 | G15: =F15+G16 | H15: =G15+H16 | I15: =H15+I16 | J15: =I15+J16 | L15: D&A p.a. ($m) | N15: 5 | O15: A | P15: Assumption
B16: $ Incremental Revenue | F16: =N13 | G16: =F16 | H16: =G16 | I16: =H16 | J16: =I16 | L16: Capex p.a. ($m) | N16: 4 | O16: A | P16: Assumption
L17: Change in NWC p.a. ($m, negative = investment) | N17: -1 | O17: A | P17: Assumption
B18: EBITDA | E18: =E19*E15 | F18: =F19*F15 | G18: =G19*G15 | H18: =H19*H15 | I18: =I19*I15 | J18: =J19*J15 | L18: Exit multiple (x) | N18: 7 | O18: A | P18: Assumed equal to entry (Herff Jones price undisclosed)
B19: % margin | E19: =N14 | F19: =E19 | G19: =F19 | H19: =G19 | I19: =H19 | J19: =I19 | L19: Entry date | N19: 40395 | O19: F | P19: Closing date per filings
L20: Underwritten exit date (5-year hold) | N20: 42221 | O20: A | P20: Template convention: five projection years
B21: LFCF Build | L21: Actual exit / valuation date | N21: n/a | O21: F | P21: No realised exit
B22: EBITDA | F22: =F18 | G22: =G18 | H22: =H18 | I22: =I18 | J22: =J18
B23: (-) D&A | F23: =-$N$15 | G23: =-$N$15 | H23: =-$N$15 | I23: =-$N$15 | J23: =-$N$15
B24: EBIT | F24: =F22+F23 | G24: =G22+G23 | H24: =H22+H23 | I24: =I22+I23 | J24: =J22+J23
B25: (-) Cash Interest | D25: =N10 | F25: =$E$12*-$D$25 | G25: =$E$12*-$D$25 | H25: =$E$12*-$D$25 | I25: =$E$12*-$D$25 | J25: =$E$12*-$D$25
B26: EBT | F26: =F24+F25 | G26: =G24+G25 | H26: =H24+H25 | I26: =I24+I25 | J26: =J24+J25
B27: (-) Taxes | D27: =N11 | F27: =F26*-$D27 | G27: =G26*-$D27 | H27: =H26*-$D27 | I27: =I26*-$D27 | J27: =J26*-$D27
B28: Net Income | F28: =F26+F27 | G28: =G26+G27 | H28: =H26+H27 | I28: =I26+I27 | J28: =J26+J27
B29: (+) D&A | F29: =-F23 | G29: =-G23 | H29: =-H23 | I29: =-I23 | J29: =-J23
B30: (-) Capex | F30: =-$N$16 | G30: =-$N$16 | H30: =-$N$16 | I30: =-$N$16 | J30: =-$N$16
B31: (-) Change in NWC | F31: =$N$17 | G31: =$N$17 | H31: =$N$17 | I31: =$N$17 | J31: =$N$17
B32: Levered FCF | F32: =SUM(F28:F31) | G32: =SUM(G28:G31) | H32: =SUM(H28:H31) | I32: =SUM(I28:I31) | J32: =SUM(J28:J31)
B33: Cumulative LFCF | F33: =SUM($E32:F32) | G33: =SUM($E32:G32) | H33: =SUM($E32:H32) | I33: =SUM($E32:I32) | J33: =SUM($E32:J32)
B35: Returns — UNDERWRITTEN CASE (template mechanics: interest on opening debt, all LFCF accumulates as cash)
B37: Exit EBITDA (2015) | E37: =J18
B38: (x) Exit Multiple | E38: =N18
B39: Enterprise Value | E39: =E37*E38
B40: (-) Debt | E40: =-E12
B41: (+) Cash | E41: =J33
B42: Equity Value at Exit | E42: =SUM(E39:E41)
B43: Initial Equity Investment | E43: =E6
B45: MoM | E45: =E42/E43
...

Sheet P06 Cerberus-Chrysler 2007
B2: Cerberus / Chrysler (2007-09) — Paper LBO
B4: Sources | G4: Uses | L4: INPUTS | N4: Value | O4: Tag | P4: Source (F = filed / rating agency, P = press, A = assumption; blue = assumption)
B5: Debt | E5: =E12 | G5: Purchase Price | J5: =J12 | L5: Entry enterprise value ($m) | N5: 17400 | O5: F | P5: Cerberus equity into Chrysler Corp LLC $5.4bn (Daimler AR 2007 / TTAC) + $12bn acquisition debt
B6: Equity (plug) | E6: =E7-E5 | L6: Entry EBITDA, LTM ($m) | N6: 1500 | O6: A | P6: Assumption: 2006 operating loss EUR(1,118)m plus segment D&A (not disclosed at segment level; group D&A implies ~$2.5-3bn incl. leasing)
B7: Total Sources | E7: =J7 | G7: Total Uses | J7: =J5 | L7: Entry multiple (x) | N7: =N5/N6 | O7: calc | P7: Derived
L8: Debt raised ($m) | N8: 12000 | O8: F | P8: $10bn first-lien TL + $2bn second-lien (Moody's / S&P, Jul-Aug 2007); $2.5bn of the 1L sat in a collateral account
B9: Build to Debt | G9: Build to Purchase Price | L9: Leverage (x EBITDA) | N9: =N8/N6 | O9: calc | P9: Derived
B10: 2006 EBITDA (LTM) | E10: =E18 | G10: 2006 EBITDA (LTM) | J10: =E18 | L10: Blended cash interest rate | N10: 0.091 | O10: A | P10: 1L assumed ~8.5% and 2L ~12% (spreads/OIDs after the failed July-2007 syndication not found)
B11: (x) Leverage | E11: =N9 | G11: (x) Multiple of 2023 EBITDA | J11: =N7 | L11: Tax rate | N11: 0.35 | O11: A | P11: Assumption
B12: Debt | E12: =E10*E11 | G12: Purchase Price | J12: =J10*J11 | L12: Base-year revenue ($m) | N12: 59000 | O12: F | P12: Chrysler Group 2006 revenue EUR47,116m (DaimlerChrysler 20-F) at ~1.25 $/EUR
L13: Incremental revenue p.a. ($m) | N13: 0 | O13: A | P13: Sponsor case: flat revenue, margin recovery via Nardelli cost plan
B14: Simple P&L | E14: 2006 | F14: =E14+1 | G14: =F14+1 | H14: =G14+1 | I14: =H14+1 | J14: =I14+1 | L14: EBITDA margin, base year | N14: =N6/N12 | O14: calc | P14: Derived
B15: Revenue | E15: =N12 | F15: =E15+F16 | G15: =F15+G16 | H15: =G15+H16 | I15: =H15+I16 | J15: =I15+J16 | L15: D&A p.a. ($m) | N15: 2800 | O15: A | P15: Assumption ~4.7% of revenue
B16: $ Incremental Revenue | F16: =N13 | G16: =F16 | H16: =G16 | I16: =H16 | J16: =I16 | L16: Capex p.a. ($m) | N16: 2000 | O16: F | P16: 2006 capex EUR1,251m; assumed ~$2.0bn
L17: Change in NWC p.a. ($m, negative = investment) | N17: 0 | O17: A | P17: Assumed flat
B18: EBITDA | E18: =E19*E15 | F18: =F19*F15 | G18: =G19*G15 | H18: =H19*H15 | I18: =I19*I15 | J18: =J19*J15 | L18: Exit multiple (x) | N18: 6 | O18: A | P18: Auto OEM exit multiple, assumption
B19: % margin | E19: =N14 | F19: 0.035 | G19: 0.045 | H19: 0.055 | I19: 0.06 | J19: 0.06 | L19: Entry date | N19: 39297 | O19: F | P19: Closing date per filings
L20: Underwritten exit date (5-year hold) | N20: 41124 | O20: A | P20: Template convention: five projection years
B21: LFCF Build | L21: Actual exit / valuation date | N21: 39933 | O21: F | P21: Realised exit date per filings
B22: EBITDA | F22: =F18 | G22: =G18 | H22: =H18 | I22: =I18 | J22: =J18
B23: (-) D&A | F23: =-$N$15 | G23: =-$N$15 | H23: =-$N$15 | I23: =-$N$15 | J23: =-$N$15
B24: EBIT | F24: =F22+F23 | G24: =G22+G23 | H24: =H22+H23 | I24: =I22+I23 | J24: =J22+J23
B25: (-) Cash Interest | D25: =N10 | F25: =$E$12*-$D$25 | G25: =$E$12*-$D$25 | H25: =$E$12*-$D$25 | I25: =$E$12*-$D$25 | J25: =$E$12*-$D$25
B26: EBT | F26: =F24+F25 | G26: =G24+G25 | H26: =H24+H25 | I26: =I24+I25 | J26: =J24+J25
B27: (-) Taxes | D27: =N11 | F27: =F26*-$D27 | G27: =G26*-$D27 | H27: =H26*-$D27 | I27: =I26*-$D27 | J27: =J26*-$D27
B28: Net Income | F28: =F26+F27 | G28: =G26+G27 | H28: =H26+H27 | I28: =I26+I27 | J28: =J26+J27
B29: (+) D&A | F29: =-F23 | G29: =-G23 | H29: =-H23 | I29: =-I23 | J29: =-J23
B30: (-) Capex | F30: =-$N$16 | G30: =-$N$16 | H30: =-$N$16 | I30: =-$N$16 | J30: =-$N$16
B31: (-) Change in NWC | F31: =$N$17 | G31: =$N$17 | H31: =$N$17 | I31: =$N$17 | J31: =$N$17
B32: Levered FCF | F32: =SUM(F28:F31) | G32: =SUM(G28:G31) | H32: =SUM(H28:H31) | I32: =SUM(I28:I31) | J32: =SUM(J28:J31)
B33: Cumulative LFCF | F33: =SUM($E32:F32) | G33: =SUM($E32:G32) | H33: =SUM($E32:H32) | I33: =SUM($E32:I32) | J33: =SUM($E32:J32)
B35: Returns — UNDERWRITTEN CASE (template mechanics: interest on opening debt, all LFCF accumulates as cash)
B37: Exit EBITDA (2011) | E37: =J18
B38: (x) Exit Multiple | E38: =N18
B39: Enterprise Value | E39: =E37*E38
B40: (-) Debt | E40: =-E12
B41: (+) Cash | E41: =J33
B42: Equity Value at Exit | E42: =SUM(E39:E41)
B43: Initial Equity Investment | E43: =E6
B45: MoM | E45: =E42/E43
...

Sheet P07 Caterpillar-Bucyrus 2011
B2: Caterpillar / Bucyrus (2011) [STRATEGIC] — Paper LBO
B3: STRATEGIC TRANSACTION, NOT AN LBO. The acquirer was a corporate; the "debt" is corporate notes and the "equity" is balance-sheet cash. The LBO template is applied only to show what the entry price required.
B4: Sources | G4: Uses | L4: INPUTS | N4: Value | O4: Tag | P4: Source (F = filed / rating agency, P = press, A = assumption; blue = assumption)
B5: Debt | E5: =E12 | G5: Purchase Price | J5: =J12 | L5: Entry enterprise value ($m) | N5: 8800 | O5: F | P5: Total purchase price as booked incl. $1.6bn assumed debt (CAT 2011 10-K)
B6: Equity (plug) | E6: =E7-E5 | L6: Entry EBITDA, LTM ($m) | N6: 637.3 | O6: F | P6: Bucyrus FY2010 EBITDA $637.3m; adjusted $720.6m (8-K Ex-99)
B7: Total Sources | E7: =J7 | G7: Total Uses | J7: =J5 | L7: Entry multiple (x) | N7: =N5/N6 | O7: calc | P7: Derived
L8: Debt raised ($m) | N8: 4500 | O8: F | P8: $4.5bn five-tranche notes, May-2011 (FWP)
B9: Build to Debt | G9: Build to Purchase Price | L9: Leverage (x EBITDA) | N9: =N8/N6 | O9: calc | P9: Derived
B10: 2010 EBITDA (LTM) | E10: =E18 | G10: 2010 EBITDA (LTM) | J10: =E18 | L10: Blended cash interest rate | N10: 0.0287 | O10: F | P10: Weighted coupon: fixed tranches 3.82%; all five ~2.87% at 3M LIBOR ~0.26%
B11: (x) Leverage | E11: =N9 | G11: (x) Multiple of 2023 EBITDA | J11: =N7 | L11: Tax rate | N11: 0.3 | O11: A | P11: Assumption
B12: Debt | E12: =E10*E11 | G12: Purchase Price | J12: =J10*J11 | L12: Base-year revenue ($m) | N12: 3650 | O12: F | P12: Bucyrus FY2010 sales (8-K Ex-99)
L13: Incremental revenue p.a. ($m) | N13: 365 | O13: A | P13: Underwritten case: ~10% p.a. plus >$400m synergies by 2015 (announcement)
B14: Simple P&L | E14: 2010 | F14: =E14+1 | G14: =F14+1 | H14: =G14+1 | I14: =H14+1 | J14: =I14+1 | L14: EBITDA margin, base year | N14: =N6/N12 | O14: calc | P14: Derived
B15: Revenue | E15: =N12 | F15: =E15+F16 | G15: =F15+G16 | H15: =G15+H16 | I15: =H15+I16 | J15: =I15+J16 | L15: D&A p.a. ($m) | N15: 100.6 | O15: F | P15: FY2010 depreciation $54.1m + amortisation $46.6m (10-K Ex-13); excludes the $3.9bn acquired-intangible amortisation
B16: $ Incremental Revenue | F16: =N13 | G16: =F16 | H16: =G16 | I16: =H16 | J16: =I16 | L16: Capex p.a. ($m) | N16: 100 | O16: F | P16: 2011 guidance ~$100m (FY2010 actual $69.4m)
L17: Change in NWC p.a. ($m, negative = investment) | N17: -50 | O17: A | P17: Assumption for a growing backlog business
B18: EBITDA | E18: =E19*E15 | F18: =F19*F15 | G18: =G19*G15 | H18: =H19*H15 | I18: =I19*I15 | J18: =J19*J15 | L18: Exit multiple (x) | N18: 10 | O18: A | P18: Mining equipment mid-cycle multiple, assumption
B19: % margin | E19: =N14 | F19: 0.19 | G19: 0.21 | H19: 0.23 | I19: 0.25 | J19: 0.26 | L19: Entry date | N19: 40732 | O19: F | P19: Closing date per filings
L20: Underwritten exit date (5-year hold) | N20: 42559 | O20: A | P20: Template convention: five projection years
B21: LFCF Build | L21: Actual exit / valuation date | N21: n/a | O21: F | P21: No realised exit
B22: EBITDA | F22: =F18 | G22: =G18 | H22: =H18 | I22: =I18 | J22: =J18
B23: (-) D&A | F23: =-$N$15 | G23: =-$N$15 | H23: =-$N$15 | I23: =-$N$15 | J23: =-$N$15
B24: EBIT | F24: =F22+F23 | G24: =G22+G23 | H24: =H22+H23 | I24: =I22+I23 | J24: =J22+J23
B25: (-) Cash Interest | D25: =N10 | F25: =$E$12*-$D$25 | G25: =$E$12*-$D$25 | H25: =$E$12*-$D$25 | I25: =$E$12*-$D$25 | J25: =$E$12*-$D$25
B26: EBT | F26: =F24+F25 | G26: =G24+G25 | H26: =H24+H25 | I26: =I24+I25 | J26: =J24+J25
B27: (-) Taxes | D27: =N11 | F27: =F26*-$D27 | G27: =G26*-$D27 | H27: =H26*-$D27 | I27: =I26*-$D27 | J27: =J26*-$D27
B28: Net Income | F28: =F26+F27 | G28: =G26+G27 | H28: =H26+H27 | I28: =I26+I27 | J28: =J26+J27
B29: (+) D&A | F29: =-F23 | G29: =-G23 | H29: =-H23 | I29: =-I23 | J29: =-J23
B30: (-) Capex | F30: =-$N$16 | G30: =-$N$16 | H30: =-$N$16 | I30: =-$N$16 | J30: =-$N$16
B31: (-) Change in NWC | F31: =$N$17 | G31: =$N$17 | H31: =$N$17 | I31: =$N$17 | J31: =$N$17
B32: Levered FCF | F32: =SUM(F28:F31) | G32: =SUM(G28:G31) | H32: =SUM(H28:H31) | I32: =SUM(I28:I31) | J32: =SUM(J28:J31)
B33: Cumulative LFCF | F33: =SUM($E32:F32) | G33: =SUM($E32:G32) | H33: =SUM($E32:H32) | I33: =SUM($E32:I32) | J33: =SUM($E32:J32)
B35: Returns — UNDERWRITTEN CASE (template mechanics: interest on opening debt, all LFCF accumulates as cash)
B37: Exit EBITDA (2015) | E37: =J18
B38: (x) Exit Multiple | E38: =N18
B39: Enterprise Value | E39: =E37*E38
B40: (-) Debt | E40: =-E12
B41: (+) Cash | E41: =J33
B42: Equity Value at Exit | E42: =SUM(E39:E41)
B43: Initial Equity Investment | E43: =E6
...

Sheet P08 NRG-DirectEnergy 2021
B2: NRG / Direct Energy (2021) [STRATEGIC] — Paper LBO
B3: STRATEGIC TRANSACTION, NOT AN LBO. The acquirer was a corporate; the "debt" is corporate notes and the "equity" is balance-sheet cash. The LBO template is applied only to show what the entry price required.
B4: Sources | G4: Uses | L4: INPUTS | N4: Value | O4: Tag | P4: Source (F = filed / rating agency, P = press, A = assumption; blue = assumption)
B5: Debt | E5: =E12 | G5: Purchase Price | J5: =J12 | L5: Entry enterprise value ($m) | N5: 3625 | O5: F | P5: Purchase price, debt-free cash-free (Centrica / NRG releases)
B6: Equity (plug) | E6: =E7-E5 | L6: Entry EBITDA, LTM ($m) | N6: 457 | O6: F | P6: 2019 underlying adjusted EBITDA $457m / GBP358m (Centrica Class 1 circular); 7.9x
B7: Total Sources | E7: =J7 | G7: Total Uses | J7: =J5 | L7: Entry multiple (x) | N7: =N5/N6 | O7: calc | P7: Derived
L8: Debt raised ($m) | N8: 2930 | O8: F | P8: $1.40bn secured notes (2.000%/2.450%) + $1.53bn unsecured (3.375%/3.625%); $900m P-Caps excluded
B9: Build to Debt | G9: Build to Purchase Price | L9: Leverage (x EBITDA) | N9: =N8/N6 | O9: calc | P9: Derived
B10: 2019 EBITDA (LTM) | E10: =E18 | G10: 2019 EBITDA (LTM) | J10: =E18 | L10: Blended cash interest rate | N10: 0.02944 | O10: F | P10: Weighted coupon on the $2.93bn: 2.944% (computed from the pricing release)
B11: (x) Leverage | E11: =N9 | G11: (x) Multiple of 2023 EBITDA | J11: =N7 | L11: Tax rate | N11: 0.21 | O11: A | P11: US federal rate
B12: Debt | E12: =E10*E11 | G12: Purchase Price | J12: =J10*J11 | L12: Base-year revenue ($m) | N12: 13935 | O12: F | P12: Direct Energy 2019 US GAAP revenue (NRG pro forma 8-K, Nov-2020)
L13: Incremental revenue p.a. ($m) | N13: 0 | O13: F | P13: Flat revenue; value case is the $300m synergy ramp
B14: Simple P&L | E14: 2019 | F14: =E14+1 | G14: =F14+1 | H14: =G14+1 | I14: =H14+1 | J14: =I14+1 | L14: EBITDA margin, base year | N14: =N6/N12 | O14: calc | P14: Derived
B15: Revenue | E15: =N12 | F15: =E15+F16 | G15: =F15+G16 | H15: =G15+H16 | I15: =H15+I16 | J15: =I15+J16 | L15: D&A p.a. ($m) | N15: 101 | O15: F | P15: Direct Energy 2019 US GAAP D&A (NRG pro forma)
B16: $ Incremental Revenue | F16: =N13 | G16: =F16 | H16: =G16 | I16: =H16 | J16: =I16 | L16: Capex p.a. ($m) | N16: 100 | O16: A | P16: Assumption (standalone capex not disclosed)
L17: Change in NWC p.a. ($m, negative = investment) | N17: 0 | O17: A | P17: Assumed flat
B18: EBITDA | E18: =E19*E15 | F18: =F19*F15 | G18: =G19*G15 | H18: =H19*H15 | I18: =I19*I15 | J18: =J19*J15 | L18: Exit multiple (x) | N18: 8 | O18: A | P18: Retail energy multiple, assumption (entry 7.9x)
B19: % margin | E19: =N14 | F19: 0.0425 | G19: 0.049 | H19: 0.0543 | I19: 0.0543 | J19: 0.0543 | L19: Entry date | N19: 44201 | O19: F | P19: Closing date per filings
L20: Underwritten exit date (5-year hold) | N20: 46027 | O20: A | P20: Template convention: five projection years
B21: LFCF Build | L21: Actual exit / valuation date | N21: n/a | O21: F | P21: No realised exit
B22: EBITDA | F22: =F18 | G22: =G18 | H22: =H18 | I22: =I18 | J22: =J18
B23: (-) D&A | F23: =-$N$15 | G23: =-$N$15 | H23: =-$N$15 | I23: =-$N$15 | J23: =-$N$15
B24: EBIT | F24: =F22+F23 | G24: =G22+G23 | H24: =H22+H23 | I24: =I22+I23 | J24: =J22+J23
B25: (-) Cash Interest | D25: =N10 | F25: =$E$12*-$D$25 | G25: =$E$12*-$D$25 | H25: =$E$12*-$D$25 | I25: =$E$12*-$D$25 | J25: =$E$12*-$D$25
B26: EBT | F26: =F24+F25 | G26: =G24+G25 | H26: =H24+H25 | I26: =I24+I25 | J26: =J24+J25
B27: (-) Taxes | D27: =N11 | F27: =F26*-$D27 | G27: =G26*-$D27 | H27: =H26*-$D27 | I27: =I26*-$D27 | J27: =J26*-$D27
B28: Net Income | F28: =F26+F27 | G28: =G26+G27 | H28: =H26+H27 | I28: =I26+I27 | J28: =J26+J27
B29: (+) D&A | F29: =-F23 | G29: =-G23 | H29: =-H23 | I29: =-I23 | J29: =-J23
B30: (-) Capex | F30: =-$N$16 | G30: =-$N$16 | H30: =-$N$16 | I30: =-$N$16 | J30: =-$N$16
B31: (-) Change in NWC | F31: =$N$17 | G31: =$N$17 | H31: =$N$17 | I31: =$N$17 | J31: =$N$17
B32: Levered FCF | F32: =SUM(F28:F31) | G32: =SUM(G28:G31) | H32: =SUM(H28:H31) | I32: =SUM(I28:I31) | J32: =SUM(J28:J31)
B33: Cumulative LFCF | F33: =SUM($E32:F32) | G33: =SUM($E32:G32) | H33: =SUM($E32:H32) | I33: =SUM($E32:I32) | J33: =SUM($E32:J32)
B35: Returns — UNDERWRITTEN CASE (template mechanics: interest on opening debt, all LFCF accumulates as cash)
B37: Exit EBITDA (2024) | E37: =J18
B38: (x) Exit Multiple | E38: =N18
B39: Enterprise Value | E39: =E37*E38
B40: (-) Debt | E40: =-E12
B41: (+) Cash | E41: =J33
B42: Equity Value at Exit | E42: =SUM(E39:E41)
B43: Initial Equity Investment | E43: =E6
...

Sheet P09 WindPoint-Pacific 2001
B2: Wind Point / Pacific Cycle (2000-04) — Paper LBO
B4: Sources | G4: Uses | L4: INPUTS | N4: Value | O4: Tag | P4: Source (F = filed / rating agency, P = press, A = assumption; blue = assumption)
B5: Debt | E5: =E12 | G5: Purchase Price | J5: =J12 | L5: Entry enterprise value ($m) | N5: 146 | O5: P | P5: $60m Brunswick bicycle business + $86m Schwinn/GT auction (Forbes, Lincoln International, Crain's)
B6: Equity (plug) | E6: =E7-E5 | L6: Entry EBITDA, LTM ($m) | N6: 22 | O6: A | P6: Assumption: ~8% margin on 2001 revenue (no EBITDA ever disclosed)
B7: Total Sources | E7: =J7 | G7: Total Uses | J7: =J5 | L7: Entry multiple (x) | N7: =N5/N6 | O7: calc | P7: Derived
L8: Debt raised ($m) | N8: 120 | O8: A | P8: Assumption: Wind Point put $3m of equity into the $60m Brunswick deal (Forbes); structure otherwise undisclosed
B9: Build to Debt | G9: Build to Purchase Price | L9: Leverage (x EBITDA) | N9: =N8/N6 | O9: calc | P9: Derived
B10: 2001 EBITDA (LTM) | E10: =E18 | G10: 2001 EBITDA (LTM) | J10: =E18 | L10: Blended cash interest rate | N10: 0.08 | O10: A | P10: Assumption
B11: (x) Leverage | E11: =N9 | G11: (x) Multiple of 2023 EBITDA | J11: =N7 | L11: Tax rate | N11: 0.38 | O11: A | P11: Assumption
B12: Debt | E12: =E10*E11 | G12: Purchase Price | J12: =J10*J11 | L12: Base-year revenue ($m) | N12: 280 | O12: P | P12: Forbes (Oct-2002): 2001 revenue ~$280m after Brunswick and Schwinn/GT
L13: Incremental revenue p.a. ($m) | N13: 22 | O13: F | P13: 2003 sales 'in excess of US$325m' (Dorel 6-K)
B14: Simple P&L | E14: 2001 | F14: =E14+1 | G14: =F14+1 | H14: =G14+1 | I14: =H14+1 | J14: =I14+1 | L14: EBITDA margin, base year | N14: =N6/N12 | O14: calc | P14: Derived
B15: Revenue | E15: =N12 | F15: =E15+F16 | G15: =F15+G16 | H15: =G15+H16 | I15: =H15+I16 | J15: =I15+J16 | L15: D&A p.a. ($m) | N15: 1 | O15: F | P15: Dorel recorded only $0.5m of segment D&A in 2004; asset-light importer
B16: $ Incremental Revenue | F16: =N13 | G16: =F16 | H16: =G16 | I16: =H16 | J16: =I16 | L16: Capex p.a. ($m) | N16: 1.5 | O16: A | P16: Assumption
L17: Change in NWC p.a. ($m, negative = investment) | N17: -3 | O17: A | P17: Growth working capital, assumption
B18: EBITDA | E18: =E19*E15 | F18: =F19*F15 | G18: =G19*G15 | H18: =H19*H15 | I18: =I19*I15 | J18: =J19*J15 | L18: Exit multiple (x) | N18: 5.8 | O18: F | P18: $310m / annualised 2004 segment EBIT $53.9m (Dorel FY2004 MD&A); D&A negligible
B19: % margin | E19: =N14 | F19: =E19 | G19: =F19 | H19: =G19 | I19: =H19 | J19: =I19 | L19: Entry date | N19: 37164 | O19: F | P19: Closing date per filings
L20: Underwritten exit date (5-year hold) | N20: 38988 | O20: A | P20: Template convention: five projection years
B21: LFCF Build | L21: Actual exit / valuation date | N21: 38020 | O21: F | P21: Realised exit date per filings
B22: EBITDA | F22: =F18 | G22: =G18 | H22: =H18 | I22: =I18 | J22: =J18
B23: (-) D&A | F23: =-$N$15 | G23: =-$N$15 | H23: =-$N$15 | I23: =-$N$15 | J23: =-$N$15
B24: EBIT | F24: =F22+F23 | G24: =G22+G23 | H24: =H22+H23 | I24: =I22+I23 | J24: =J22+J23
B25: (-) Cash Interest | D25: =N10 | F25: =$E$12*-$D$25 | G25: =$E$12*-$D$25 | H25: =$E$12*-$D$25 | I25: =$E$12*-$D$25 | J25: =$E$12*-$D$25
B26: EBT | F26: =F24+F25 | G26: =G24+G25 | H26: =H24+H25 | I26: =I24+I25 | J26: =J24+J25
B27: (-) Taxes | D27: =N11 | F27: =F26*-$D27 | G27: =G26*-$D27 | H27: =H26*-$D27 | I27: =I26*-$D27 | J27: =J26*-$D27
B28: Net Income | F28: =F26+F27 | G28: =G26+G27 | H28: =H26+H27 | I28: =I26+I27 | J28: =J26+J27
B29: (+) D&A | F29: =-F23 | G29: =-G23 | H29: =-H23 | I29: =-I23 | J29: =-J23
B30: (-) Capex | F30: =-$N$16 | G30: =-$N$16 | H30: =-$N$16 | I30: =-$N$16 | J30: =-$N$16
B31: (-) Change in NWC | F31: =$N$17 | G31: =$N$17 | H31: =$N$17 | I31: =$N$17 | J31: =$N$17
B32: Levered FCF | F32: =SUM(F28:F31) | G32: =SUM(G28:G31) | H32: =SUM(H28:H31) | I32: =SUM(I28:I31) | J32: =SUM(J28:J31)
B33: Cumulative LFCF | F33: =SUM($E32:F32) | G33: =SUM($E32:G32) | H33: =SUM($E32:H32) | I33: =SUM($E32:I32) | J33: =SUM($E32:J32)
B35: Returns — UNDERWRITTEN CASE (template mechanics: interest on opening debt, all LFCF accumulates as cash)
B37: Exit EBITDA (2006) | E37: =J18
B38: (x) Exit Multiple | E38: =N18
B39: Enterprise Value | E39: =E37*E38
B40: (-) Debt | E40: =-E12
B41: (+) Cash | E41: =J33
B42: Equity Value at Exit | E42: =SUM(E39:E41)
B43: Initial Equity Investment | E43: =E6
B45: MoM | E45: =E42/E43
...

Sheet P10 Pegasus-Cannondale 2003
B2: Pegasus Capital / Cannondale (2003-08) — Paper LBO
B4: Sources | G4: Uses | L4: INPUTS | N4: Value | O4: Tag | P4: Source (F = filed / rating agency, P = press, A = assumption; blue = assumption)
B5: Debt | E5: =E12 | G5: Purchase Price | J5: =J12 | L5: Entry enterprise value ($m) | N5: 58 | O5: P | P5: Bicycle assets bought for ~$55m at the 20 Mar 2003 auction; '~$58m' per Bicycle Retailer
B6: Equity (plug) | E6: =E7-E5 | L6: Entry EBITDA, LTM ($m) | N6: 8 | O6: A | P6: Assumption: post-emergence ~5.7% margin (FY2002 operating loss $(12.2)m)
B7: Total Sources | E7: =J7 | G7: Total Uses | J7: =J5 | L7: Entry multiple (x) | N7: =N5/N6 | O7: calc | P7: Derived
L8: Debt raised ($m) | N8: 30 | O8: A | P8: Assumption: CIT provided DIP and exit financing; quantum undisclosed
B9: Build to Debt | G9: Build to Purchase Price | L9: Leverage (x EBITDA) | N9: =N8/N6 | O9: calc | P9: Derived
B10: 2003 EBITDA (LTM) | E10: =E18 | G10: 2003 EBITDA (LTM) | J10: =E18 | L10: Blended cash interest rate | N10: 0.09 | O10: A | P10: Assumption
B11: (x) Leverage | E11: =N9 | G11: (x) Multiple of 2023 EBITDA | J11: =N7 | L11: Tax rate | N11: 0.38 | O11: A | P11: Assumption
B12: Debt | E12: =E10*E11 | G12: Purchase Price | J12: =J10*J11 | L12: Base-year revenue ($m) | N12: 140 | O12: A | P12: Assumption: FY2002 sales $156.7m (last 10-K) less the retained motorsports line and the bankruptcy year
L13: Incremental revenue p.a. ($m) | N13: 12 | O13: F | P13: Cannondale + Sugoi ~$200m sales in 2007 (Dorel 6-K)
B14: Simple P&L | E14: 2003 | F14: =E14+1 | G14: =F14+1 | H14: =G14+1 | I14: =H14+1 | J14: =I14+1 | L14: EBITDA margin, base year | N14: =N6/N12 | O14: calc | P14: Derived
B15: Revenue | E15: =N12 | F15: =E15+F16 | G15: =F15+G16 | H15: =G15+H16 | I15: =H15+I16 | J15: =I15+J16 | L15: D&A p.a. ($m) | N15: 4 | O15: A | P15: Assumption
B16: $ Incremental Revenue | F16: =N13 | G16: =F16 | H16: =G16 | I16: =H16 | J16: =I16 | L16: Capex p.a. ($m) | N16: 4 | O16: A | P16: Assumption
L17: Change in NWC p.a. ($m, negative = investment) | N17: -2 | O17: A | P17: Assumption
B18: EBITDA | E18: =E19*E15 | F18: =F19*F15 | G18: =G19*G15 | H18: =H19*H15 | I18: =I19*I15 | J18: =J19*J15 | L18: Exit multiple (x) | N18: 9.75 | O18: A | P18: $195m midpoint / ~$20m 2007 EBITDA (assumption; Dorel disclosed sales only)
B19: % margin | E19: =N14 | F19: 0.07 | G19: 0.08 | H19: 0.09 | I19: 0.1 | J19: 0.1 | L19: Entry date | N19: 37700 | O19: F | P19: Closing date per filings
L20: Underwritten exit date (5-year hold) | N20: 39527 | O20: A | P20: Template convention: five projection years
B21: LFCF Build | L21: Actual exit / valuation date | N21: 39482 | O21: F | P21: Realised exit date per filings
B22: EBITDA | F22: =F18 | G22: =G18 | H22: =H18 | I22: =I18 | J22: =J18
B23: (-) D&A | F23: =-$N$15 | G23: =-$N$15 | H23: =-$N$15 | I23: =-$N$15 | J23: =-$N$15
B24: EBIT | F24: =F22+F23 | G24: =G22+G23 | H24: =H22+H23 | I24: =I22+I23 | J24: =J22+J23
B25: (-) Cash Interest | D25: =N10 | F25: =$E$12*-$D$25 | G25: =$E$12*-$D$25 | H25: =$E$12*-$D$25 | I25: =$E$12*-$D$25 | J25: =$E$12*-$D$25
B26: EBT | F26: =F24+F25 | G26: =G24+G25 | H26: =H24+H25 | I26: =I24+I25 | J26: =J24+J25
B27: (-) Taxes | D27: =N11 | F27: =F26*-$D27 | G27: =G26*-$D27 | H27: =H26*-$D27 | I27: =I26*-$D27 | J27: =J26*-$D27
B28: Net Income | F28: =F26+F27 | G28: =G26+G27 | H28: =H26+H27 | I28: =I26+I27 | J28: =J26+J27
B29: (+) D&A | F29: =-F23 | G29: =-G23 | H29: =-H23 | I29: =-I23 | J29: =-J23
B30: (-) Capex | F30: =-$N$16 | G30: =-$N$16 | H30: =-$N$16 | I30: =-$N$16 | J30: =-$N$16
B31: (-) Change in NWC | F31: =$N$17 | G31: =$N$17 | H31: =$N$17 | I31: =$N$17 | J31: =$N$17
B32: Levered FCF | F32: =SUM(F28:F31) | G32: =SUM(G28:G31) | H32: =SUM(H28:H31) | I32: =SUM(I28:I31) | J32: =SUM(J28:J31)
B33: Cumulative LFCF | F33: =SUM($E32:F32) | G33: =SUM($E32:G32) | H33: =SUM($E32:H32) | I33: =SUM($E32:I32) | J33: =SUM($E32:J32)
B35: Returns — UNDERWRITTEN CASE (template mechanics: interest on opening debt, all LFCF accumulates as cash)
B37: Exit EBITDA (2008) | E37: =J18
B38: (x) Exit Multiple | E38: =N18
B39: Enterprise Value | E39: =E37*E38
B40: (-) Debt | E40: =-E12
B41: (+) Cash | E41: =J33
B42: Equity Value at Exit | E42: =SUM(E39:E41)
B43: Initial Equity Investment | E43: =E6
B45: MoM | E45: =E42/E43
...

Sheet P11 Cerberus-Dorel 2021 TERM
B2: Cerberus + Koch / Dorel (2021) [TERMINATED] — Paper LBO
B4: Sources | G4: Uses | L4: INPUTS | N4: Value | O4: Tag | P4: Source (F = filed / rating agency, P = press, A = assumption; blue = assumption)
B5: Debt | E5: =E12 | G5: Purchase Price | J5: =J12 | L5: Entry enterprise value ($m) | N5: 1012 | O5: F | P5: Aggregate purchase price incl. assumed debt and ~$65m fees (Dorel release, 1 Feb 2021); ~8.5x
B6: Equity (plug) | E6: =E7-E5 | L6: Entry EBITDA, LTM ($m) | N6: 119.6 | O6: F | P6: Buyer's adjusted LTM EBITDA to 30 Sep 2020 (Dorel release, 1 Feb 2021); Letko says it embeds $44.5m of downward adjustments
B7: Total Sources | E7: =J7 | G7: Total Uses | J7: =J5 | L7: Entry multiple (x) | N7: =N5/N6 | O7: calc | P7: Derived
L8: Debt raised ($m) | N8: 500 | O8: F | P8: Funded debt from third-party lenders (Dorel release, 1 Feb 2021)
B9: Build to Debt | G9: Build to Purchase Price | L9: Leverage (x EBITDA) | N9: =N8/N6 | O9: calc | P9: Derived
B10: 2020 EBITDA (LTM) | E10: =E18 | G10: 2020 EBITDA (LTM) | J10: =E18 | L10: Blended cash interest rate | N10: 0.07 | O10: A | P10: Assumption
B11: (x) Leverage | E11: =N9 | G11: (x) Multiple of 2023 EBITDA | J11: =N7 | L11: Tax rate | N11: 0.26 | O11: A | P11: Canadian blended, assumption
B12: Debt | E12: =E10*E11 | G12: Purchase Price | J12: =J10*J11 | L12: Base-year revenue ($m) | N12: 2762.5 | O12: F | P12: Dorel FY2020 revenue (Q4-2020 results)
L13: Incremental revenue p.a. ($m) | N13: 80 | O13: A | P13: ~3% p.a., assumption
B14: Simple P&L | E14: 2020 | F14: =E14+1 | G14: =F14+1 | H14: =G14+1 | I14: =H14+1 | J14: =I14+1 | L14: EBITDA margin, base year | N14: =N6/N12 | O14: calc | P14: Derived
B15: Revenue | E15: =N12 | F15: =E15+F16 | G15: =F15+G16 | H15: =G15+H16 | I15: =H15+I16 | J15: =I15+J16 | L15: D&A p.a. ($m) | N15: 98.1 | O15: F | P15: FY2020 consolidated D&A (cash-flow statement)
B16: $ Incremental Revenue | F16: =N13 | G16: =F16 | H16: =G16 | I16: =H16 | J16: =I16 | L16: Capex p.a. ($m) | N16: 40 | O16: A | P16: Assumption
L17: Change in NWC p.a. ($m, negative = investment) | N17: 0 | O17: A | P17: Assumed flat
B18: EBITDA | E18: =E19*E15 | F18: =F19*F15 | G18: =G19*G15 | H18: =H19*H15 | I18: =I19*I15 | J18: =J19*J15 | L18: Exit multiple (x) | N18: 8.5 | O18: A | P18: Assumed equal to entry
B19: % margin | E19: =N14 | F19: =E19 | G19: =F19 | H19: =G19 | I19: =H19 | J19: =I19 | L19: Entry date | N19: 44243 | O19: F | P19: Closing date per filings
L20: Underwritten exit date (5-year hold) | N20: 46069 | O20: A | P20: Template convention: five projection years
B21: LFCF Build | L21: Actual exit / valuation date | N21: 46069 | O21: F | P21: Realised exit date per filings
B22: EBITDA | F22: =F18 | G22: =G18 | H22: =H18 | I22: =I18 | J22: =J18
B23: (-) D&A | F23: =-$N$15 | G23: =-$N$15 | H23: =-$N$15 | I23: =-$N$15 | J23: =-$N$15
B24: EBIT | F24: =F22+F23 | G24: =G22+G23 | H24: =H22+H23 | I24: =I22+I23 | J24: =J22+J23
B25: (-) Cash Interest | D25: =N10 | F25: =$E$12*-$D$25 | G25: =$E$12*-$D$25 | H25: =$E$12*-$D$25 | I25: =$E$12*-$D$25 | J25: =$E$12*-$D$25
B26: EBT | F26: =F24+F25 | G26: =G24+G25 | H26: =H24+H25 | I26: =I24+I25 | J26: =J24+J25
B27: (-) Taxes | D27: =N11 | F27: =F26*-$D27 | G27: =G26*-$D27 | H27: =H26*-$D27 | I27: =I26*-$D27 | J27: =J26*-$D27
B28: Net Income | F28: =F26+F27 | G28: =G26+G27 | H28: =H26+H27 | I28: =I26+I27 | J28: =J26+J27
B29: (+) D&A | F29: =-F23 | G29: =-G23 | H29: =-H23 | I29: =-I23 | J29: =-J23
B30: (-) Capex | F30: =-$N$16 | G30: =-$N$16 | H30: =-$N$16 | I30: =-$N$16 | J30: =-$N$16
B31: (-) Change in NWC | F31: =$N$17 | G31: =$N$17 | H31: =$N$17 | I31: =$N$17 | J31: =$N$17
B32: Levered FCF | F32: =SUM(F28:F31) | G32: =SUM(G28:G31) | H32: =SUM(H28:H31) | I32: =SUM(I28:I31) | J32: =SUM(J28:J31)
B33: Cumulative LFCF | F33: =SUM($E32:F32) | G33: =SUM($E32:G32) | H33: =SUM($E32:H32) | I33: =SUM($E32:I32) | J33: =SUM($E32:J32)
B35: Returns — UNDERWRITTEN CASE (template mechanics: interest on opening debt, all LFCF accumulates as cash)
B37: Exit EBITDA (2025) | E37: =J18
B38: (x) Exit Multiple | E38: =N18
B39: Enterprise Value | E39: =E37*E38
B40: (-) Debt | E40: =-E12
B41: (+) Cash | E41: =J33
B42: Equity Value at Exit | E42: =SUM(E39:E41)
B43: Initial Equity Investment | E43: =E6
B45: MoM | E45: =E42/E43
...

Sheet F01 KKR-Varsity 2024
B1: KKR / Varsity Brands (2024) — Full LBO model (template: LBO Model Solution)
B2: Assumptions | L2: INPUT NOTES
B3: Entry Multiple | E3: 11.875 | G3: TL | I3: 6.1875 | J3: 0.0225 | L3: EBITDA at entry $400m and entry multiple 11.875x reproduce the filed/reported purchase price of $4,750m.
B4: Exit Multiple | E4: 11 | G4: Mezz | I4: 0 | J4: 0 | L4: Term loan 6.1875x EBITDA at 9.05%; mezz/second-lien 0.0x at 0.00%.
B5: EBITDA at Entry | E5: 400 | G5: Days | I5: 365 | L5: Purchase-accounting inputs (NPV of assets, PP&E allocation, DTL rate), working-capital days and D&A/capex ratios are assumptions unless the paper tab's source column says otherwise.
B6: Financing Fees Years | E6: 7 | G6: Tax Rate | I6: 0.25 | L6: Sensitivity tables (rows 173-186) are Excel data tables and recompute when opened in Excel; other spreadsheet apps may show the last cached values.
B7: D&A Life | E7: 15 | L7: Three template formulas are corrected on this tab so the model survives negative cash flow: CFF now includes the revolver draw (row 89); a negative cash balance no longer triggers a second revolver draw (row 110); the term-loan sweep only uses cash that exists (row 120). With positive cash flow the results are identical to the original.
B8: Rollover | E8: 0 | G8: circ | I8: 1 | J8: << interest is charged on opening balances on this tab, so no iteration is needed; 1 keeps interest on | L8: Interest is charged on opening balances, which removes the template's circular reference; switch I8 is left at 1 so the interest lines stay live.
B10: Sources | G10: Uses
B11: Term Loan | E11: =+I3*$E$5 | G11: Equity purchase price | J11: =+E18
B12: Mezz Loan | E12: =+I4*$E$5 | G12: M&A fee | J12: 70
